<?xml version="1.0" encoding="utf-8"?>
<!-- This URDF was automatically created by SolidWorks to URDF Exporter! Originally created by Stephen Brawner (brawner@gmail.com) 
     Commit Version: 1.6.0-1-g15f4949  Build Version: 1.6.7594.29634
     For more information, please see http://wiki.ros.org/sw_urdf_exporter -->
<robot
  name="solo8_URDF_v4">
  <link
    name="base_link">
    <inertial>
      <origin
        xyz="-0.000131243804565513 -2.1877512663984E-07 -0.0434999979123721"
        rpy="0 0 0" />
      <mass
        value="1.08310148935514" />
      <inertia
        ixx="0.00078292100000959"
        ixy="-2.4726499499223E-09"
        ixz="-3.63300254721981E-10"
        iyy="0.00259878031126529"
        iyz="-1.55590918624866E-08"
        izz="0.00245312418407862" />
    </inertial>
    <visual>
      <origin
        xyz="0 0 0"
        rpy="0 0 0" />
      <geometry>
        <mesh
          filename="base_link.obj" />
      </geometry>
      <material
        name="">
        <color
          rgba="0.752941176470588 0.752941176470588 0.752941176470588 1" />
      </material>
    </visual>
    <collision>
      <origin
        xyz="0 0 0"
        rpy="0 0 0" />
      <!-- <geometry>
        <mesh
          filename="base_link.obj" />
      </geometry> -->
      <geometry>
        <box size="0.2 0.2 0.1"/>
      </geometry>
    </collision>
  </link>
  <link
    name="rear_left_upper_leg">
    <inertial>
      <origin
        xyz="0.0260463560497017 1.96058726216197E-05 0.0818383915482504"
        rpy="0 0 0" />
      <mass
        value="0.0878533269246308" />
      <inertia
        ixx="0.000160165468405235"
        ixy="5.98615459821546E-09"
        ixz="-1.01735410352558E-05"
        iyy="0.00015477566312305"
        iyz="7.25231006351549E-08"
        izz="1.45900829531821E-05" />
    </inertial>
    <visual>
      <origin
        xyz="0 0 0"
        rpy="0 0 0" />
      <geometry>
        <mesh
          filename="rear_left_upper_leg.obj" />
      </geometry>
      <material
        name="">
        <color
          rgba="0.752941176470588 0.752941176470588 0.752941176470588 1" />
      </material>
    </visual>
    <collision>
      <origin
        xyz="0 0 0"
        rpy="0 0 0" />
      <!-- <geometry>
        <mesh
          filename="rear_left_upper_leg.obj" />
      </geometry> -->
      <geometry>
        <box size="0.1 0.1 0.1"/>
      </geometry>
    </collision>
  </link>
  <joint
    name="HL_HFE"
    type="revolute">
    <origin
      xyz="0.19 -0.09805 -0.0435"
      rpy="3.1416 0 -1.5708" />
    <parent
      link="base_link" />
    <child
      link="rear_left_upper_leg" />
    <axis
      xyz="1 0 0" />
    <limit
      lower="-10"
      upper="10"
      effort="1000"
      velocity="1000" />
  </joint>
  <link
    name="rear_left_lower_leg">
    <inertial>
      <origin
        xyz="0.00798615918661305 -1.97240518362563E-09 0.0871955396993983"
        rpy="0 0 0" />
      <mass
        value="0.0568162066846248" />
      <inertia
        ixx="0.000116328623228087"
        ixy="-1.4413584564191E-12"
        ixz="-2.14214688984561E-06"
        iyy="0.000115301324090038"
        iyz="-6.13770553608215E-10"
        izz="3.92621698046174E-06" />
    </inertial>
    <visual>
      <origin
        xyz="0 0 0"
        rpy="0 0 0" />
      <geometry>
        <mesh
          filename="front_left_lower_leg.obj" />
      </geometry>
      <material
        name="">
        <color
          rgba="0.752941176470588 0.752941176470588 0.752941176470588 1" />
      </material>
    </visual>
    <collision>
      <origin
        xyz="0 0 0"
        rpy="0 0 0" />
     <!--  <geometry>
        <mesh
          filename="front_left_lower_leg.obj" />
      </geometry> -->
      <geometry>
        <box size="0.1 0.1 0.1"/>
      </geometry>
    </collision>
  </link>
  <joint
    name="HL_KFE"
    type="revolute">
    <origin
      xyz="0.0519500000000016 0 0.16"
      rpy="-1.5707963267949 0 -3.14159265358979" />
    <parent
      link="rear_left_upper_leg" />
    <child
      link="rear_left_lower_leg" />
    <axis
      xyz="1 0 0" />
    <limit
      lower="-10"
      upper="10"
      effort="1000"
      velocity="1000" />
  </joint>

  <link
    name="rear_right_upper_leg">
    <inertial>
      <origin
        xyz="0.0260463416796457 0.0818382398206385 -1.96475353925196E-05"
        rpy="0 0 0" />
      <mass
        value="0.0878534992285754" />
      <inertia
        ixx="0.000160166486207479"
        ixy="-1.0173668173731E-05"
        ixz="-6.02181345311133E-09"
        iyy="1.45901216597277E-05"
        iyz="-7.2801573302373E-08"
        izz="0.000154776708796327" />
    </inertial>
    <visual>
      <origin
        xyz="0 0 0"
        rpy="0 0 0" />
      <geometry>
        <mesh
          filename="rear_right_upper_leg.obj" />
      </geometry>
      <material
        name="">
        <color
          rgba="0.752941176470588 0.752941176470588 0.752941176470588 1" />
      </material>
    </visual>
    <collision>
      <origin
        xyz="0 0 0"
        rpy="0 0 0" />
      <!-- <geometry>
        <mesh
          filename="rear_right_upper_leg.obj" />
      </geometry> -->
      <geometry>
        <box size="0.1 0.1 0.1"/>
      </geometry>
    </collision>
  </link>
  <joint
    name="HR_HFE"
    type="revolute">
    <origin
      xyz="0.19 0.09805 -0.0435"
      rpy="-1.5708 0 1.5708" />
    <parent
      link="base_link" />
    <child
      link="rear_right_upper_leg" />
    <axis
      xyz="1 0 0" />
    <limit
      lower="-10"
      upper="10"
      effort="1000"
      velocity="1000" />
  </joint>
  <link
    name="rear_right_lower_leg">
    <inertial>
      <origin
        xyz="-0.00797510895141648 2.02971700558052E-09 0.0871955400372977"
        rpy="0 0 0" />
      <mass
        value="0.0568162062662583" />
      <inertia
        ixx="0.000116328622478411"
        ixy="-1.44920779054025E-12"
        ixz="2.14214690301966E-06"
        iyy="0.000115301448850468"
        iyz="7.24188217803086E-10"
        izz="3.92609149618552E-06" />
    </inertial>
    <visual>
      <origin
        xyz="0 0 0"
        rpy="0 0 0" />
      <geometry>
        <mesh
          filename="front_right_lower_leg.obj" />
      </geometry>
      <material
        name="">
        <color
          rgba="0.752941176470588 0.752941176470588 0.752941176470588 1" />
      </material>
    </visual>
    <collision>
      <origin
        xyz="0 0 0"
        rpy="0 0 0" />
      <!-- <geometry>
        <mesh
          filename="front_right_lower_leg.obj" />
      </geometry> -->
      <geometry>
        <box size="0.1 0.1 0.1"/>
      </geometry>
    </collision>
  </link>
  <joint
    name="HR_KFE"
    type="revolute">
    <origin
      xyz="0.051950000000001 0.16 0"
      rpy="0 0 -3.1416" />
    <parent
      link="rear_right_upper_leg" />
    <child
      link="rear_right_lower_leg" />
    <axis
      xyz="-1 0 0" />
    <limit
      lower="-10"
      upper="10"
      effort="1000"
      velocity="1000" />
  </joint>
  
  <link
    name="front_left_upper_leg">
    <inertial>
      <origin
        xyz="0.0260463213501499 1.96051061115143E-05 0.0818380959136073"
        rpy="0 0 0" />
      <mass
        value="0.0878537035476835" />
      <inertia
        ixx="0.000160165160326423"
        ixy="5.97988996236533E-09"
        ixz="-1.01734766862367E-05"
        iyy="0.000154775389279724"
        iyz="7.2491964765402E-08"
        izz="1.45901195907274E-05" />
    </inertial>
    <visual>
      <origin
        xyz="0 0 0"
        rpy="0 0 0" />
      <geometry>
        <mesh
          filename="front_left_upper_leg.obj" />
      </geometry>
      <material
        name="">
        <color
          rgba="0.752941176470588 0.752941176470588 0.752941176470588 1" />
      </material>
    </visual>
    <collision>
      <origin
        xyz="0 0 0"
        rpy="0 0 0" />
     <!--  <geometry>
        <mesh
          filename="front_left_upper_leg.obj" />
      </geometry> -->
      <geometry>
        <box size="0.1 0.1 0.1"/>
      </geometry>
    </collision>
  </link>
  <joint
    name="FL_HFE"
    type="revolute">
    <origin
      xyz="-0.19 -0.09805 -0.0435"
      rpy="3.1416 0 -1.5708" />
    <parent
      link="base_link" />
    <child
      link="front_left_upper_leg" />
    <axis
      xyz="1 0 0" />
    <limit
      lower="-10"
      upper="10"
      effort="1000"
      velocity="1000" />
  </joint>
  <link
    name="front_left_lower_leg">
    <inertial>
      <origin
        xyz="0.000812954907024432 -0.0709663568959096 3.16708653191888E-08"
        rpy="0 0 0" />
      <mass
        value="0.0352176463863073" />
      <inertia
        ixx="0.000102544957886135"
        ixy="-1.95338237262207E-06"
        ixz="-1.83862183857662E-12"
        iyy="1.73308119670232E-06"
        iyz="-6.55038614981896E-11"
        izz="0.000101666357617047" />
    </inertial>
    <visual>
      <origin
        xyz="0 0 0"
        rpy="0 0 0" />
      <geometry>
        <mesh
          filename="front_left_lower_leg.obj" />
      </geometry>
      <material
        name="">
        <color
          rgba="0.752941176470588 0.752941176470588 0.752941176470588 1" />
      </material>
    </visual>
    <collision>
      <origin
        xyz="0 0 0"
        rpy="0 0 0" />
     <!--  <geometry>
        <mesh
          filename="front_left_lower_leg.obj" />
      </geometry> -->
      <geometry>
        <box size="0.1 0.1 0.1"/>
      </geometry>
    </collision>
  </link>
  <joint
    name="FL_KFE"
    type="revolute">
    <origin
      xyz="0.0519500000000016 0 0.16"
      rpy="-1.5707963267949 0 -3.14159265358979" />
    <parent
      link="front_left_upper_leg" />
    <child
      link="front_left_lower_leg" />
    <axis
      xyz="-1 0 0" />
    <limit
      lower="-10"
      upper="10"
      effort="1000"
      velocity="1000" />
  </joint>
  <link
    name="front_right_upper_leg">
    <inertial>
      <origin
        xyz="0.0260462217616799 0.0818371669464919 -1.96409034333711E-05"
        rpy="0 0 0" />
      <mass
        value="0.087854821599005" />
      <inertia
        ixx="0.000160172872993533"
        ixy="-1.01744862780989E-05"
        ixz="-6.02462268517269E-09"
        iyy="1.45900414152232E-05"
        iyz="-7.28060149796806E-08"
        izz="0.000154783006946061" />
    </inertial>
    <visual>
      <origin
        xyz="0 0 0"
        rpy="0 0 0" />
      <geometry>
        <mesh
          filename="front_right_upper_leg.obj" />
      </geometry>
      <material
        name="">
        <color
          rgba="0.752941176470588 0.752941176470588 0.752941176470588 1" />
      </material>
    </visual>
    <collision>
      <origin
        xyz="0 0 0"
        rpy="0 0 0" />
      <!-- <geometry>
        <mesh
          filename="front_right_upper_leg.obj" />
      </geometry> -->
      <geometry>
        <box size="0.1 0.1 0.1"/>
      </geometry>
    </collision>
  </link>
  <joint
    name="FR_HFE"
    type="revolute">
    <origin
      xyz="-0.190000000000001 0.0980500000000003 -0.0434999999999995"
      rpy="-1.5707963267949 0 1.5707963267949" />
    <parent
      link="base_link" />
    <child
      link="front_right_upper_leg" />
    <axis
      xyz="1 0 0" />
    <limit
      lower="-10"
      upper="10"
      effort="1000"
      velocity="1000" />
  </joint>
  <link
    name="front_right_lower_leg">
    <inertial>
      <origin
        xyz="0.00081295491320274 -0.0709663564341324 3.1561713798034E-08"
        rpy="0 0 0" />
      <mass
        value="0.0352176467961685" />
      <inertia
        ixx="0.000102544958492936"
        ixy="-1.95338234788562E-06"
        ixz="-1.84048280454168E-12"
        iyy="1.73308122040895E-06"
        iyz="-6.53557905951406E-11"
        izz="0.000101666358172514" />
    </inertial>
    <visual>
      <origin
        xyz="0 0 0"
        rpy="0 0 0" />
      <geometry>
        <mesh
          filename="front_right_lower_leg.obj" />
      </geometry>
      <material
        name="">
        <color
          rgba="0.752941176470588 0.752941176470588 0.752941176470588 1" />
      </material>
    </visual>
    <collision>
      <origin
        xyz="0 0 0"
        rpy="0 0 0" />
      <!-- <geometry>
        <mesh
          filename="front_right_lower_leg.obj" />
      </geometry> -->
      <geometry>
        <box size="0.1 0.1 0.1"/>
      </geometry>
    </collision>
  </link>
  <joint
    name="FR_KFE"
    type="revolute">
    <origin
      xyz="0.051950000000001 0.16 0"
      rpy="0 0 -3.14159265358979" />
    <parent
      link="front_right_upper_leg" />
    <child
      link="front_right_lower_leg" />
    <axis
      xyz="-1 0 0" />
    <limit
      lower="-10"
      upper="10"
      effort="1000"
      velocity="1000" />
  </joint>
</robot>